<?xml version="1.0" encoding="utf-8"?>
<robot name="ur5">
    <link name="base_link">
      <visual>
      	<origin xyz= "0 0 0" rpy="0 0 0"/>
        <geometry>
          <mesh filename="../meshes/ur5/visual/base.dae"/>
        </geometry>
        <material name="LightGrey">
          <color rgba="0.3 0.3 0.7 1.0"/>
        </material>
      </visual>
    </link>
    <joint name="shoulder_pan_joint" type="revolute">
      <parent link="base_link"/>
      <child link= "shoulder_link" />
      <origin xyz="0.0 0.0 0.089159" rpy="0.0 0.0 0.0" />
      <axis xyz="0 0 1" />
      <limit lower="-3.14" upper="3.14" effort="20.0" velocity="3.15"/>
      <dynamics damping="0.0" friction="0.0"/>
    </joint>

    <link name="shoulder_link">
      <visual>
        <origin rpy= "0 0 0" xyz= "0 0 0.0"/> 
        <geometry>
          <mesh filename="../meshes/ur5/visual/shoulder.dae" />
        </geometry>
        <material name="LightGrey">
          <color rgba="1.0 1.0 0.5 1.0"/>
        </material>
      </visual>
      <inertial>
      	<origin xyz= "0.0 0.0 0.0" rpy= "0 0 0"/>
      	<mass value = "3.70"/>
      	<inertia ixx= "0.010267" ixy= "0.0" ixz="0.0" iyy="0.010267" iyz="0.0" izz="0.00666"/>
      </inertial>
    </link>

    <joint name="shoulder_lift_joint" type="revolute">
      <parent link="shoulder_link" />
      <child link = "upper_arm_link" />
      <origin xyz="0.0 0.13585 0.0" rpy="0.0 1.570796327 0.0" />
      <axis xyz="0 1 0" />
      <limit lower="-3.141592" upper="3.141592" effort="150.0" velocity="3.15"/>
      <dynamics damping="0.0" friction="0.0"/>
    </joint>

    <link name="upper_arm_link">
      <visual>
      	<origin xyz="0.0 0.0 0.0" rpy="0 0 0" />
        <geometry>
          <mesh filename="../meshes/ur5/visual/upperarm.dae" />
        </geometry>
        <material name="LightGrey">
          <color rgba="0.7 0.7 0.7 1.0"/>
        </material>
      </visual>
    </link>

    <joint name="elbow_joint" type="revolute">
      <parent link="upper_arm_link" />
      <child link = "forearm_link" />
      <origin xyz="0.0 -0.1197 0.42500" rpy="0.0 0.0 0.0" />
      <axis xyz="0 1 0" />
      <limit lower="-3.141592654" upper="3.141592654" effort="150.0" velocity="3.15"/>
      <dynamics damping="0.0" friction="0.0"/>
    </joint>

    <link name="forearm_link">
      <visual>
      	<origin xyz="0.0 0.0 0.00" rpy="0 0 0" />
        <geometry>
          <mesh filename="../meshes/ur5/visual/forearm.dae"/>
        </geometry>
        <material name="LightGrey">
          <color rgba="0.7 0.7 0.7 1.0"/>
        </material>
      </visual>
    </link>

    <joint name="wrist_1_joint" type="revolute">
      <parent link="forearm_link" />
      <child link = "wrist_1_link" />
      <origin xyz="0.0 0.0 0.39225" rpy="0.0 1.570796327 0.0" />
      <axis xyz="0 1 0" />
      <limit lower="-3.1415" upper="3.1415" effort="28.0" velocity="3.2"/>
      <dynamics damping="0.0" friction="0.0"/>
    </joint>

    <link name="wrist_1_link">
      <visual>
      	<origin xyz="0.0 0.0 0.00" rpy="0 0 0" />
        <geometry>
          <mesh filename="../meshes/ur5/visual/wrist1.dae" />
        </geometry>
        <material name="LightGrey">
          <color rgba="0.7 0.7 0.7 1.0"/>
        </material>
      </visual>
    </link>
    
    <joint name="wrist_2_joint" type="revolute">
    	<parent link="wrist_1_link" />
    	<child link= "wrist_2_link" />
    	<origin xyz="0.0 0.093 0.0" rpy="0 0 0"/>
    	<axis xyz="0 0 1"/>
    	<limit lower="-3.1415" upper="3.1415" effort="28.0" velocity="3.2"/>
    	<dynamics damping="0.0" friction="0.0"/>
    </joint>
    <link name= "wrist_2_link">
    	<visual>
      	  <origin xyz="0.0 0.0 0.00" rpy="0 0 0" />
          <geometry>
            <mesh filename="../meshes/ur5/visual/wrist2.dae" />
          </geometry>
        <material name="LightGrey">
          <color rgba="0.7 0.7 0.7 1.0"/>
        </material>
      </visual>
    </link>
    
    <joint name= "wrist_3_joint" type="revolute">
    	<parent link="wrist_2_link"/>
    	<child link="wrist_3_link"/>
    	<origin xyz="0.0 0.0 0.09465" rpy="0 0 0"/>
    	<axis xyz= "0 1 0"/>
    	<limit lower="-3.1415" upper="3.1415" effort="28.0" velocity="3.2"/>
    	<dynamics damping="0.0" friction="0.0"/>
    </joint>
    <link name= "wrist_3_link">
    	<visual>
      	  <origin xyz="0.0 0.0 0.00" rpy="0 0 0" />
          <geometry>
            <mesh filename="../meshes/ur5/visual/wrist3.dae" />
          </geometry>
        <material name="LightGrey">
          <color rgba="0.7 0.7 0.7 1.0"/>
        </material>
      </visual>
    </link>    
    <joint name="ee_fixed_joint" type="fixed">
      <parent link= "wrist_3_link"/>
      <child link= "ee_link"/>
      <origin xyz= "0 0.0823 0.0" rpy="0 0 1.57079"/>
    </joint>
    <link name="ee_link">
    </link>
    <!-- ROS base_link to UR 'Base' Coordinates transform -->
    <link name="base"/>
    <joint name="base_link-base_fixed_joint" type="fixed">
      <!-- NOTE: this rotation is only needed as long as base_link itself is
                 not corrected wrt the real robot (ie: rotated over 180
                 degrees)
      -->
      <origin xyz="0 0 0" rpy="0 0 0"/>
      <parent link="base_link"/>
      <child link="base"/>
    </joint>

    <!-- Frame coincident with all-zeros TCP on UR controller -->

</robot>
